Workbook

Sheet Cost and Key Assumptions
B1: Assumptions | C1: Value | D1: Notes | H1: How Big is 2,000 tokens?
B2: Students (WTAMU) | C2: 10000
B3: AVG tokens per class/day | C3: =C5 -> 2000
B4: AVG total tokens per day | C4: =C3*C12 -> 10000
B5: AVG Tokens per conversation | C5: 2000
B6: AVG Weekly tokens per student | C6: =C4*6 -> 60000 | D6: (MON-FRI) - 1/2 day SAT, SUN
B7: AVG Conversations student/semester | C7: =(C6*15)/2000 -> 450
B8: Tokens per student/semester | C8: =C7*C5 -> 900000
B9: Cost per 1M input tokens | C9: 0.15
B10: Cost per 1M output tokens | C10: 0.6
B11: Input:Output token Ratio | C11: 60/40
B12: AVG classes per student/semester | C12: 5
B13: Semesters per Year | C13: 2
B16: Token Cost Calculation | H16: Token usage per Conversation
B17: Input tokens per student | C17: =C8*0.6 -> 540000
B18: Output tokens per student | C18: =C8*0.4 -> 360000
B21: Cost per Student per Semester
B22: Input cost per student | C22: =(C17/1000000)*C9 -> 0.081
B23: Output cost per student | C23: =(C18/1000000)*C10 -> 0.216
B24: Total API cost per student/Semester | C24: =C22+C23 -> 0.297
B25: Annual API cost per student | C25: =C24*C13 -> 0.594
B28: Campus-Wide API Cost
B29: Annual tokens (all students) | C29: =C8*C2*C13 -> 18000000000
B30: Total Annual cost (Input tokens) | C30: =(C29*0.6/1000000)*C9 -> 1620
B31: Total Annual cost (Output tokens) | C31: =(C29*0.4/1000000)*C10 -> 4320
B32: Total Annual API Cost | C32: =C30+C31 -> 5940
B35: Estimated MVP Development Costs (CAPEX)
B36: Backend service for scoring engine | C36: 6000
B37: Student dashboard UI | C37: 4000
B38: Instructor Dashboard UI | C38: 3000
B39: Database + Intergration | C39: 1500
B40: Authentication + roles | C40: 1000
B41: QA + Deployment + testing | C41: 1500
B42: Total Annual API Cost | C42: =C32 -> 5940
B43: ≈ Total MVP Development Cost | C43: =SUM(C36:C42) -> 22940
B46: Employee Compensation
B47: Founder CEO Base Annual Salary | C47: 100000
B48: Contract DEV Support (YR1 MVP Build) | C48: 65000
B49: Product Enhancement & Major Feature DEV BUDGET (Annual) | C49: 80000
B53: Ongoing Maintenance Costs | E53: 3 month total | F53: 6 Month Total (1 semester)
...

Sheet Revenue Model
B1: Revenue Assumptions | C1: Value
B2: Engineering Maintenance (annual) | C2: ='Cost and Key Assumptions'!C56*12 -> 42000
B3: Infrastructure (annual) | C3: ='Cost and Key Assumptions'!C67*12 -> 2460
B4: SaaS tools (annual) | C4: ='Cost and Key Assumptions'!C75*12 -> 1500
B5: Annual API Costs per Student | C5: ='Cost and Key Assumptions'!C25 -> 0.594
B6: Total Annual OPEX | C6: ='Cost and Key Assumptions'!C81 -> 45960
B7: Students | C7: ='Cost and Key Assumptions'!C2 -> 10000
B8: Cost per Student per YEAR | C8: =C6/C7 -> 4.596
B9: Cost per Student per SEMESTER | C9: =C8/2 -> 2.298
B10: Initial Capital Expenditure | C10: ='Cost and Key Assumptions'!C43 -> 22940
B11: Total Annual OPEX & CAPEX | C11: =C6+C10 -> 68900
B12: COGS | C12: =C5 -> 0.594
B13: EBITDA | C13: =E18-C6-(C7*C5) -> 188100
B14: NWC as 3% of (Standart) Revenue for SaaS | C14: =0.03*E18 -> 7200
B16: Pricing Tiers | C16: Price / Semester | D16: Price / Year | E16: Revenue | F16: Gross Profit
B17: Minimum Viable Pricing (Break Even) | C17: 2.595 | D17: =C17*2 -> 5.19 | E17: =D17*$C$7 -> 51900 | F17: =E17-$C$6-($C$5*$C$7) -> 1.4551915e-11
B18: Standard | C18: 12 | D18: =C18*2 -> 24 | E18: =D18*$C$7 -> 240000 | F18: =E18-$C$6 -> 194040
B19: Premium | C19: 16 | D19: =C19*2 -> 32 | E19: =D19*$C$7 -> 320000 | F19: =E19-$C$6 -> 274040
B20: Annual Institution Licensing Fee | C20: 10000 | D20: - | E20: - | F20: -
B22: WTAMU Pilot Pricing
B23: year 1 (Life Time A.I.L Fee waiver) | C23: 12 | D23: =C23*2 -> 24 | E23: =D23*C7 -> 240000 | F23: =E23-C10-C6-($C$5*$C$7) -> 165160
B24: year 2 | C24: =C18 -> 12 | D24: =C24*2 -> 24 | E24: =D24*C7 -> 240000 | F24: =E24-C6 -> 194040

Sheet NPV & FCF Model
A1: NPV for AI Compliance app
A3: Assumptions
A4: Initial Capital Expenditure (Year 0) | B4: ='Revenue Model'!C10 -> 22940
A5: Useful Life of Assets (in year) | B5: 5
A6: Annual Depreciation | B6: =B4/B5 -> 4588
A7: EBITDA/Sales profit margin (Standard subscription price 10k students | B7: =('Revenue Model'!C13)/('Revenue Model'!C20+'Revenue Model'!E18) -> 0.7524
A8: Baseline Operating (OPEX) | B8: ='Revenue Model'!C6 -> 45960
A9: CEO Salary | B9: ='Cost and Key Assumptions'!C47 -> 100000
A10: Contract DEV (YR1 only) | B10: ='Cost and Key Assumptions'!C48 -> 65000
A11: Feature DEV BUDGET (YR 2-5) | B11: ='Cost and Key Assumptions'!C49 -> 80000
A12: Variable Costs (Annual API per Student) | B12: ='Revenue Model'!C5 -> 0.594
A13: Standard Pricing per Student | B13: ='Revenue Model'!D18 -> 24
A14: Number of Students | B14: ='Revenue Model'!C7 -> 10000
A15: Initial Net working capital as 3% of (Standard) Revenue Sales (Year 0) | B15: ='Revenue Model'!C14 -> 7200
A16: Tax Rate | B16: 0.21
A17: Cost of Capital | B17: 0.18
A18: Revenues in Year 1 (WTAMU Pilot Pricing) | B18: ='Revenue Model'!E23 -> 240000
A19: WTAMU 1st year Pricing per student | B19: ='Revenue Model'!D17 -> 5.19
A20: Annual Institution Licensing Fee | B20: ='Revenue Model'!C20 -> 10000
A21: Enrollment CAGR | C21: 0 | D21: 0.4 | E21: 0.4 | F21: 0.4 | G21: 0.2
B22: Year | C22: Year | D22: Year | E22: Year | F22: Year | G22: Year
B23: 2026 | C23: =B23+1 -> 2027 | D23: =C23+1 -> 2028 | E23: =D23+1 -> 2029 | F23: =E23+1 -> 2030 | G23: =F23+1 -> 2031
A24: Unlevered Income Statements | B24: 0 | C24: 1 | D24: 2 | E24: 3 | F24: 4 | G24: 5
A25: Number of Schools licensed | C25: 1 | D25: 2 | E25: 3 | F25: 4 | G25: 5
A26: Revenue Generated from (AIL) | C26: =C25*$B$20 -> 10000 | D26: =D25*$B$20 -> 20000 | E26: =E25*$B$20 -> 30000 | F26: =F25*$B$20 -> 40000 | G26: =G25*$B$20 -> 50000
A27: Revenues | C27: {=($B$20*C25) + ($B$14*$B$13*PRODUCT(1+$C$21:C$21))} -> 250000 | D27: {=($B$20*D25) + ($B$14*$B$13*PRODUCT(1+$C$21:D$21))} -> 356000 | E27: {=($B$20*E25) + ($B$14*$B$13*PRODUCT(1+$C$21:E$21))} -> 500400 | F27: {=($B$20*F25) + ($B$14*$B$13*PRODUCT(1+$C$21:F$21))} -> 698560 | G27: {=($B$20*G25) + ($B$14*$B$13*PRODUCT(1+$C$21:G$21))} -> 840272
A28: Variable Costs (API per Student) | C28: =$B$12*$B$14 -> 5940 | D28: =$B$12*$B$14 -> 5940 | E28: =$B$12*$B$14 -> 5940 | F28: =$B$12*$B$14 -> 5940 | G28: =$B$12*$B$14 -> 5940 | J28: need to revisit my variable API cost and include the enrollment CAGR
A29: Annual Operating Expenses (OPEX) | C29: =$B$8+$B$9+$B$10 -> 210960 | D29: =$B$8+$B$9+$B$11 -> 225960 | E29: =$B$8+$B$9+$B$11 -> 225960 | F29: =$B$8+$B$9+$B$11 -> 225960 | G29: =$B$8+$B$9+$B$11 -> 225960
A30: EBITDA | C30: =C27-C28-C29 -> 33100 | D30: =D27-D28-D29 -> 124100 | E30: =E27-E28-E29 -> 268500 | F30: =F27-F28-F29 -> 466660 | G30: =G27-G28-G29 -> 608372
A31: Depreciation | C31: =$B$6 -> 4588 | D31: =$B$6 -> 4588 | E31: =$B$6 -> 4588 | F31: =$B$6 -> 4588 | G31: =$B$6 -> 4588
A32: Tax | C32: =(C30-C31)*$B$16 -> 5987.52 | D32: =(D30-D31)*$B$16 -> 25097.52 | E32: =(E30-E31)*$B$16 -> 55421.52 | F32: =(F30-F31)*$B$16 -> 97035.12 | G32: =(G30-G31)*$B$16 -> 126794.64
A33: Unlevered Net Income | C33: =(C30-C31)*(1-$B$16) -> 22524.48 | D33: =(D30-D31)*(1-$B$16) -> 94414.48 | E33: =(E30-E31)*(1-$B$16) -> 208490.48 | F33: =(F30-F31)*(1-$B$16) -> 365036.88 | G33: =(G30-G31)*(1-$B$16) -> 476989.36
A35: Working Capital Calculations
A36: NWC Level | B36: =B15 -> 7200 | C36: =0.03*C27 -> 7500 | D36: =0.03*D27 -> 10680 | E36: =0.03*E27 -> 15012 | F36: =0.03*F27 -> 20956.8 | G36: =0.03*G27 -> 25208.16
A37: Change in NWC | C37: =C36-B36 -> 300 | D37: =D36-C36 -> 3180 | E37: =E36-D36 -> 4332 | F37: =F36-E36 -> 5944.8 | G37: =G36-F36 -> 4251.36
A38: CF from Change in NWC | C38: =-C37 -> -300 | D38: =-D37 -> -3180 | E38: =-E37 -> -4332 | F38: =-F37 -> -5944.8 | G38: =-G37 -> -4251.36
A40: Calculating Free Cash Flows
A41: Unlevered Net Income | C41: =C33 -> 22524.48 | D41: =D33 -> 94414.48 | E41: =E33 -> 208490.48 | F41: =F33 -> 365036.88 | G41: =G33 -> 476989.36
A42: Add Back Depreciation | C42: =C31 -> 4588 | D42: =D31 -> 4588 | E42: =E31 -> 4588 | F42: =F31 -> 4588 | G42: =G31 -> 4588
A43: Subtract Change in NWC | C43: =C37 -> 300 | D43: =D37 -> 3180 | E43: =E37 -> 4332 | F43: =F37 -> 5944.8 | G43: =G37 -> 4251.36
...

Sheet Sensitivity Analysis
A1: The following graph is meaningful only if the scenario is set to the Base-Case.
A2: Figure 11-3
A3: Sensitivity Graph for OP Papertrail APP Project (Dollars in Thousands)
B26: Data for Sensitivity Graph
B27: Deviation | C27: NPV with Variables at Different Deviations from Base
B28: from Base | C28: Equip. | D28: Price | E28: Sales (Students) | F28: VC/API per Student
B29: ='NPV & FCF Model'!D59 -> -0.3 | C29: ='NPV & FCF Model'!F59 -> 618738.71 | D29: ='NPV & FCF Model'!J59 -> 253636.02 | E29: ='NPV & FCF Model'!H59 -> 258038.39 | F29: ='NPV & FCF Model'!L59 -> 589078.31
B30: ='NPV & FCF Model'!D60 -> 0 | C30: ='NPV & FCF Model'!F60 -> 584675.94 | D30: ='NPV & FCF Model'!J60 -> 584675.94 | E30: ='NPV & FCF Model'!H60 -> 584675.94 | F30: ='NPV & FCF Model'!L60 -> 584675.94
B31: ='NPV & FCF Model'!D61 -> 0.3 | C31: ='NPV & FCF Model'!F61 -> 550613.17 | D31: ='NPV & FCF Model'!J61 -> 915715.86 | E31: ='NPV & FCF Model'!H61 -> 911313.49 | F31: ='NPV & FCF Model'!L61 -> 580273.57
B32: Range | C32: =ABS(C29-C31) -> 68125.546 | D32: =ABS(D29-D31) -> 662079.83 | E32: =ABS(E29-E31) -> 653275.1 | F32: =ABS(F29-F31) -> 8804.7376
A36: Figure 11-4 | J36: NPV with Variables at Different Deviations from Base | O36: Scratch for Tornado Diagram Below
A37: Tornado Diagram for OP Papertrail APP Project: Range of Outcomes for Input Deviations from Base-Case (Dollars in Thousands) | J37: Equip. | K37: Price | L37: Units | M37: VC/Unit
I38: X-values for diagram below | J38: =C29 -> 618738.71 | K38: =D29 -> 253636.02 | L38: =E29 -> 258038.39 | M38: =F29 -> 589078.31 | O38: Base NPV = | P38: Y-axis
J39: =C30 -> 584675.94 | K39: =D30 -> 584675.94 | L39: =E30 -> 584675.94 | M39: =F30 -> 584675.94 | O39: ='NPV & FCF Model'!$B$49 -> 584675.94 | P39: 5
J40: =C31 -> 550613.17 | K40: =D31 -> 915715.86 | L40: =E31 -> 911313.49 | M40: =F31 -> 580273.57 | O40: =O39 -> 584675.94 | P40: 4
O41: =O40 -> 584675.94 | P41: 1
J43: Rank of Range of NPV from Sensitivity Table Above
J44: Equipment | K44: Price | L44: Units | M44: VC/Unit
I45: Range | J45: =C32 -> 68125.546 | K45: =D32 -> 662079.83 | L45: =E32 -> 653275.1 | M45: =F32 -> 8804.7376
I46: Rank | J46: 2 | K46: 4 | L46: 3 | M46: 1
I47: Y-values for diagram below | J47: =J46 -> 2 | K47: =K46 -> 4 | L47: =L46 -> 3 | M47: =M46 -> 1
J48: =J47 -> 2 | K48: =K47 -> 4 | L48: =L47 -> 3 | M48: =M47 -> 1
J49: =J48 -> 2 | K49: =K48 -> 4 | L49: =L48 -> 3 | M49: =M48 -> 1

Sheet Scenario Analysis
A1: Figure 11-5 | J1: Analysis for Scenario Shown Below: | T1: Analysis for Scenario Shown Below: | AD1: Analysis for Scenario Shown Below:
A2: Inputs and Key Results for Each Scenario (Dollars in Thousands) | J2: =E4 -> Worst-Case | T2: =F4 -> Base-Case | AD2: =G4 -> Best-Case
E3: Scenarios: | J3: Intermediate Calculations | N3: 0 | O3: 1 | P3: 2 | Q3: 3 | R3: 4 | T3: Intermediate Calculations | X3: 0 | Y3: 1 | Z3: 2 | AA3: 3 | AB3: 4 | AD3: Intermediate Calculations | AH3: 0 | AI3: 1 | AJ3: 2 | AK3: 3 | AL3: 4
A4: Scenario Name | E4: Worst-Case | F4: Base-Case | G4: Best-Case | J4: Unit sales (BASE) | O4: 10000 | P4: 10000 | Q4: 10000 | R4: 10000 | T4: Unit sales (BASE) | Y4: 10000 | Z4: 10000 | AA4: 10000 | AB4: 10000 | AD4: Unit sales (BASE) | AH4: 10000 | AI4: 10000 | AJ4: 10000 | AK4: 10000 | AL4: 10000
J5: CAGR From Base (Adoption Growth) | O5: 0 | P5: 0 | Q5: 0 | R5: 0 | T5: CAGR From Base (Adoption Growth) | Y5: 0 | Z5: 0.4 | AA5: 0.4 | AB5: 0.4 | AD5: CAGR From Base (Adoption Growth) | AI5: 9 | AJ5: 1.5 | AK5: 0.8 | AL5: 0.22
A6: Probability of Scenario | E6: 0.25 | F6: 0.5 | G6: 0.25 | J6: Sales price per unit | O6: 24 | P6: ='NPV & FCF Model'!B13 -> 24 | Q6: =P6*(1+$E$47) -> 24 | R6: =Q6*(1+$E$47) -> 24 | T6: Sales price per unit | Y6: ='NPV & FCF Model'!B13 -> 24 | Z6: =Y6*(1+$F$47) -> 24 | AA6: =Z6*(1+$F$47) -> 24 | AB6: =AA6*(1+$F$47) -> 24 | AD6: Sales price per unit | AI6: ='NPV & FCF Model'!$B$13 -> 24 | AJ6: ='NPV & FCF Model'!$B$13 -> 24 | AK6: ='NPV & FCF Model'!$B$13 -> 24 | AL6: ='NPV & FCF Model'!$B$13 -> 24
A7: Inputs: | J7: AIL # of Schools | O7: 1 | P7: 1 | Q7: 1 | R7: 1 | T7: AIL # of Schools Licensed | Y7: 1 | Z7: 2 | AA7: 3 | AB7: 4 | AD7: AIL # of Schools Licensed | AI7: 10 | AJ7: 25 | AK7: 45 | AL7: 55
A8: Equipment cost (CAPEX) | E8: ='Cost and Key Assumptions'!$C$43 -> 22940 | F8: ='Cost and Key Assumptions'!$C$43 -> 22940 | G8: ='Cost and Key Assumptions'!$C$43 -> 22940 | J8: # of Students (Users) Annual | O8: =O4 -> 10000 | P8: =P4 -> 10000 | Q8: =Q4 -> 10000 | R8: =R4 -> 10000 | T8: # of Students (users) Annual | Y8: =Y4 -> 10000 | Z8: =Y8*(1+Z5) -> 14000 | AA8: =Z8*(1+AA5) -> 19600 | AB8: =AA8*(1+AB5) -> 27440 | AD8: # of Students (Users) Annual | AI8: =AI4*AI5+AH4 -> 100000 | AJ8: =AI8*(1+AJ5) -> 250000 | AK8: =AJ8*(1+AK5) -> 450000 | AL8: =AK8*(1+AL5) -> 549000
A9: Salvage value of equip. in Year 4 | E9: 0 | F9: 0 | G9: 0 | J9: Annual AIL (BASE) Fee | O9: 10000 | P9: 10000 | Q9: 10000 | R9: 10000 | T9: Annual AIL (BASE) Fee | Y9: ='NPV & FCF Model'!C26 -> 10000 | Z9: 10000 | AA9: 10000 | AB9: 10000 | AD9: Annual AIL (BASE) Fee | AI9: ='NPV & FCF Model'!$B$20 -> 10000 | AJ9: ='NPV & FCF Model'!$B$20 -> 10000 | AK9: ='NPV & FCF Model'!$B$20 -> 10000 | AL9: ='NPV & FCF Model'!$B$20 -> 10000
A10: Opportunity cost | E10: =N33 -> 21504.743 | F10: =X33 -> 21417.164 | G10: =AH33 -> 22940 | J10: Variable cost per unit (excl. depr.) | O10: ='NPV & FCF Model'!K61 -> 0.7722 | P10: =O10*(1+$E$49) -> 0.7722 | Q10: =P10*(1+$E$49) -> 0.7722 | R10: =Q10*(1+$E$49) -> 0.7722 | T10: Variable cost per unit (excl. depr.) | Y10: ='NPV & FCF Model'!K60 -> 0.594 | Z10: =Y10*(1+$F$49) -> 0.594 | AA10: =Z10*(1+$F$49) -> 0.594 | AB10: =AA10*(1+$F$49) -> 0.594 | AD10: Variable cost per unit (excl. depr.) | AI10: ='NPV & FCF Model'!$K$60 -> 0.594 | AJ10: =AI10*(1+$G$49) -> 0.594 | AK10: =AJ10*(1+$G$49) -> 0.594 | AL10: =AK10*(1+$G$49) -> 0.594
A11: Externalities (cannibalization) | E11: 0 | F11: 0 | G11: 0 | J11: Nonvariable costs (excl. depr.) | O11: ='NPV & FCF Model'!E61+'NPV & FCF Model'!C29-'NPV & FCF Model'!B8 -> 224748 | P11: ='NPV & FCF Model'!$E$61+'NPV & FCF Model'!D29-'NPV & FCF Model'!$B$8 -> 239748 | Q11: ='NPV & FCF Model'!$E$61+'NPV & FCF Model'!E29-'NPV & FCF Model'!$B$8 -> 239748 | R11: ='NPV & FCF Model'!$E$61+'NPV & FCF Model'!F29-'NPV & FCF Model'!$B$8 -> 239748 | T11: Nonvariable costs (excl. depr.) | Y11: ='NPV & FCF Model'!C29 -> 210960 | Z11: ='NPV & FCF Model'!D29 -> 225960 | AA11: ='NPV & FCF Model'!E29 -> 225960 | AB11: ='NPV & FCF Model'!F29 -> 225960 | AD11: Nonvariable costs (excl. depr.) | AI11: ='NPV & FCF Model'!$E$59+'NPV & FCF Model'!C29-'NPV & FCF Model'!$B$8 -> 197172 | AJ11: ='NPV & FCF Model'!$E$59+'NPV & FCF Model'!D29-'NPV & FCF Model'!$B$8 -> 212172 | AK11: ='NPV & FCF Model'!$E$59+'NPV & FCF Model'!E29-'NPV & FCF Model'!$B$8 -> 212172 | AL11: ='NPV & FCF Model'!$E$59+'NPV & FCF Model'!F29-'NPV & FCF Model'!$B$8 -> 212172
A12: Units sold, Year 1 | E12: =O4 -> 10000 | F12: =Y8 -> 10000 | G12: =AI8 -> 100000 | J12: Sales revenues = Users × Price/unit | O12: =O4*O6+O9 -> 250000 | P12: =P4*P6+P9 -> 250000 | Q12: =Q4*Q6+Q9 -> 250000 | R12: =R4*R6+R9 -> 250000 | T12: Sales revenues = Users × Price/unit | Y12: =(Y8*Y6)+(Y7*Y9) -> 250000 | Z12: =(Z8*Z6)+(Z7*Z9) -> 356000 | AA12: =(AA8*AA6)+(AA7*AA9) -> 500400 | AB12: =(AB8*AB6)+(AB7*AB9) -> 698560 | AD12: Sales revenues = Users × Price/unit | AI12: =(AI8*AI6)+(AI7*AI9) -> 2500000 | AJ12: =(AJ8*AJ6)+(AJ7*AJ9) -> 6250000 | AK12: =(AK8*AK6)+(AK7*AK9) -> 11250000 | AL12: =(AL8*AL6)+(AL7*AL9) -> 13726000
A13: Units sold, Year 2, Pct. change from Year 1 | E13: 0 | F13: =Z5 -> 0.4 | G13: =AJ5 -> 1.5 | J13: NOWCt = 10%(Revenuest+1) | N13: ='NPV & FCF Model'!B36 -> 7200 | O13: =O12*$E$24 -> 25000 | P13: =P12*$E$24 -> 25000 | Q13: =Q12*$E$24 -> 25000 | R13: =R12*$E$24 -> 25000 | T13: NOWCt = 10%(Revenuest+1) (YR4 10% of annual revenue YR3) | X13: =N13 -> 7200 | Y13: =Z12*$F$24 -> 35600 | Z13: =AA12*$F$24 -> 50040 | AA13: =AB12*$F$24 -> 69856 | AB13: =(AB12*1.1)*$F$24 -> 76841.6 | AD13: NOWCt = 10%(Revenuest+1)(YR4 10% of annual revenue YR3) | AH13: ='NPV & FCF Model'!B15 -> 7200 | AI13: =AJ12*$G$24 -> 625000 | AJ13: =AK12*$G$24 -> 1125000 | AK13: =AL12*$G$24 -> 1372600 | AL13: =(AL12*1.1)*$G$24 -> 1509860
A14: Units sold, Year 3, Pct. change from Year 1 | E14: 0 | F14: =AA5 -> 0.4 | G14: =AK5 -> 0.8 | J14: Basis for depreciation | N14: =E8 -> 22940 | T14: Basis for depreciation | X14: =F8 -> 22940 | AD14: Basis for depreciation | AH14: =G8 -> 22940
A15: Units sold, Year 4, Pct. change from Year 1 | E15: 0 | F15: =AB5 -> 0.4 | G15: =AL5 -> 0.22 | J15: Annual depreciation rate (MACRS) | O15: 0.3333 | P15: 0.4445 | Q15: 0.1481 | R15: 0.0741 | T15: Annual depreciation rate (MACRS) | Y15: 0.3333 | Z15: 0.4445 | AA15: 0.1481 | AB15: 0.0741 | AD15: Annual depreciation rate (MACRS) | AI15: 0.3333 | AJ15: 0.4445 | AK15: 0.1481 | AL15: 0.0741
A16: Sales price per unit, Year 1 | E16: 12 | F16: =Y6 -> 24 | G16: =AI6 -> 24 | J16: Annual depreciation expense | O16: =$N$14*O15 -> 7645.902 | P16: =$N$14*P15 -> 10196.83 | Q16: =$N$14*Q15 -> 3397.414 | R16: =$N$14*R15 -> 1699.854 | T16: Annual depreciation expense | Y16: =$X$14*Y15 -> 7645.902 | Z16: =$X$14*Z15 -> 10196.83 | AA16: =$X$14*AA15 -> 3397.414 | AB16: =$X$14*AB15 -> 1699.854 | AD16: Annual depreciation expense | AI16: =$AH$14*AI15 -> 7645.902 | AJ16: =$AH$14*AJ15 -> 10196.83 | AK16: =$AH$14*AK15 -> 3397.414 | AL16: =$AH$14*AL15 -> 1699.854
A17: % Δ in sales price, after Year 1 | E17: 0 | F17: 0 | G17: 0 | J17: Remaining undepreciated value | O17: =N14-O16 -> 15294.098 | P17: =O17-P16 -> 5097.268 | Q17: =P17-Q16 -> 1699.854 | R17: =Q17-R16 -> 0 | T17: Remaining undepreciated value | Y17: =X14-Y16 -> 15294.098 | Z17: =Y17-Z16 -> 5097.268 | AA17: =Z17-AA16 -> 1699.854 | AB17: =AA17-AB16 -> 0 | AD17: Remaining undepreciated value | AI17: =AH14-AI16 -> 15294.098 | AJ17: =AI17-AJ16 -> 5097.268 | AK17: =AJ17-AK16 -> 1699.854 | AL17: =AK17-AL16 -> 0
A18: Var. cost per unit (VC), Year 1 | E18: =O10 -> 0.7722 | F18: =Y10 -> 0.594 | G18: =AI10 -> 0.594 | J18: Cash Flow Forecast | O18: Cash Flows at End of Year | T18: Cash Flow Forecast | Y18: Cash Flows at End of Year | AD18: Cash Flow Forecast | AI18: Cash Flows at End of Year
A19: % Δ in VC, after Year 1 | E19: 0 | F19: 0 | G19: 0 | N19: 0 | O19: 1 | P19: 2 | Q19: 3 | R19: 4 | X19: 0 | Y19: 1 | Z19: 2 | AA19: 3 | AB19: 4 | AH19: 0 | AI19: 1 | AJ19: 2 | AK19: 3 | AL19: 4
A20: Nonvar. cost (Non-VC), Year 1 | E20: =O22 -> 224748 | F20: =Y11 -> 210960 | G20: =AI11 -> 197172 | J20: Sales revenues = Users × Price/unit | O20: =O4*O6 -> 240000 | P20: =P4*P6 -> 240000 | Q20: =Q4*Q6 -> 240000 | R20: =R4*R6 -> 240000 | T20: Sales revenues = Users × Price/unit | Y20: =Y12 -> 250000 | Z20: =Z12 -> 356000 | AA20: =AA12 -> 500400 | AB20: =AB12 -> 698560 | AD20: Sales revenues = Users × Price/unit | AI20: =AI12 -> 2500000 | AJ20: =AJ12 -> 6250000 | AK20: =AK12 -> 11250000 | AL20: =AL12 -> 13726000
A21: % Δ in Non-VC, after Year 1 | E21: =(P11-O11)/P11 -> 0.062565694 | F21: =(Z11-Y11)/Z11 -> 0.066383431 | G21: =(AJ11-AI11)/AJ11 -> 0.070697359 | J21: Variable costs = Users × Cost/unit | O21: =O4*O10 -> 7722 | P21: =P4*P10 -> 7722 | Q21: =Q4*Q10 -> 7722 | R21: =R4*R10 -> 7722 | T21: Variable costs = Users × Cost/unit | Y21: {=(Y4*Y10)*PRODUCT(1+$Y$5:Y5)} -> 5940 | Z21: {=(Z4*Z10)*PRODUCT(1+$Y$5:Z5)} -> 8316 | AA21: {=(AA4*AA10)*PRODUCT(1+$Y$5:AA5)} -> 11642.4 | AB21: {=(AB4*AB10)*PRODUCT(1+$Y$5:AB5)} -> 16299.36 | AD21: Variable costs = Users × Cost/unit | AI21: =AI8*AI10 -> 59400 | AJ21: =AJ8*AJ10 -> 148500 | AK21: =AK8*AK10 -> 267300 | AL21: =AL8*AL10 -> 326106
A22: Project WACC | E22: 0.22 | F22: 0.18 | G22: 0.16 | J22: Nonvariable costs (excluding depreciation) | O22: =O11 -> 224748 | P22: =P11 -> 239748 | Q22: =Q11 -> 239748 | R22: =R11 -> 239748 | T22: Nonvariable costs (excluding depreciation) | Y22: =Y11 -> 210960 | Z22: =Z11 -> 225960 | AA22: =AA11 -> 225960 | AB22: =AB11 -> 225960 | AD22: Nonvariable costs (excluding depreciation) | AI22: =AI11 -> 197172 | AJ22: =AJ11 -> 212172 | AK22: =AK11 -> 212172 | AL22: =AL11 -> 212172
A23: Tax rate | E23: 0.25 | F23: ='NPV & FCF Model'!B16 -> 0.21 | G23: 0.25 | J23: Depreciation | O23: =O16 -> 7645.902 | P23: =P16 -> 10196.83 | Q23: =Q16 -> 3397.414 | R23: =R16 -> 1699.854 | T23: Depreciation | Y23: =Y16 -> 7645.902 | Z23: =Z16 -> 10196.83 | AA23: =AA16 -> 3397.414 | AB23: =AB16 -> 1699.854 | AD23: Depreciation | AI23: =AI16 -> 7645.902 | AJ23: =AJ16 -> 10196.83 | AK23: =AK16 -> 3397.414 | AL23: =AL16 -> 1699.854
A24: NOWC as % of next year's sales | E24: 0.1 | F24: 0.1 | G24: 0.1 | J24: Earnings before interest and taxes (EBIT) | O24: =O20-O21-O22-O23 -> -115.902 | P24: =P20-P21-P22-P23 -> -17666.83 | Q24: =Q20-Q21-Q22-Q23 -> -10867.414 | R24: =R20-R21-R22-R23 -> -9169.854 | T24: Earnings before interest and taxes (EBIT) | Y24: =Y20-Y21-Y22-Y23 -> 25454.098 | Z24: =Z20-Z21-Z22-Z23 -> 111527.17 | AA24: =AA20-AA21-AA22-AA23 -> 259400.19 | AB24: =AB20-AB21-AB22-AB23 -> 454600.79 | AD24: Earnings before interest and taxes (EBIT) | AI24: =AI20-AI21-AI22-AI23 -> 2235782.1 | AJ24: =AJ20-AJ21-AJ22-AJ23 -> 5879131.2 | AK24: =AK20-AK21-AK22-AK23 -> 10767131 | AL24: =AL20-AL21-AL22-AL23 -> 13186022
A25: Key Results: | J25: Taxes on operating profit (25% rate) | O25: =O24*$E$23 -> -28.9755 | P25: =P24*$E$23 -> -4416.7075 | Q25: =Q24*$E$23 -> -2716.8535 | R25: =R24*$E$23 -> -2292.4635 | T25: Taxes on operating profit (21% rate) | Y25: =Y24*$F$23 -> 5345.3606 | Z25: =Z24*$F$23 -> 23420.706 | AA25: =AA24*$F$23 -> 54474.039 | AB25: =AB24*$F$23 -> 95466.165 | AD25: Taxes on operating profit (25% rate) | AI25: =AI24*$G$23 -> 558945.52 | AJ25: =AJ24*$G$23 -> 1469782.8 | AK25: =AK24*$G$23 -> 2691782.6 | AL25: =AL24*$G$23 -> 3296505.5
D26: NPV = | E26: =L37 -> 9519.9547 | F26: =V37 -> 385921.56 | G26: =AF37 -> 14270571 | J26: Net operating profit after taxes | O26: =O24-O25 -> -86.9265 | P26: =P24-P25 -> -13250.123 | Q26: =Q24-Q25 -> -8150.5605 | R26: =R24-R25 -> -6877.3905 | T26: Net operating profit after taxes | Y26: =Y24-Y25 -> 20108.737 | Z26: =Z24-Z25 -> 88106.464 | AA26: =AA24-AA25 -> 204926.15 | AB26: =AB24-AB25 -> 359134.62 | AD26: Net operating profit after taxes | AI26: =AI24-AI25 -> 1676836.6 | AJ26: =AJ24-AJ25 -> 4409348.4 | AK26: =AK24-AK25 -> 8075347.9 | AL26: =AL24-AL25 -> 9889516.6
D27: IRR = | E27: =L38 -> 0.38047451 | F27: =V38 -> 2.1070146 | G27: =AF38 -> 38.624367 | J27: Add back depreciation | O27: =O23 -> 7645.902 | P27: =P23 -> 10196.83 | Q27: =Q23 -> 3397.414 | R27: =R23 -> 1699.854 | T27: Add back depreciation | Y27: =Y23 -> 7645.902 | Z27: =Z23 -> 10196.83 | AA27: =AA23 -> 3397.414 | AB27: =AB23 -> 1699.854 | AD27: Add back depreciation | AI27: =AI23 -> 7645.902 | AJ27: =AJ23 -> 10196.83 | AK27: =AK23 -> 3397.414 | AL27: =AL23 -> 1699.854
D28: MIRR = | E28: =L39 -> 0.31056157 | F28: =V39 -> 1.30206 | G28: =AF39 -> 4.4139169 | J28: Project recurring cash flows | O28: =O26+O27 -> 7558.9755 | P28: =P26+P27 -> -3053.2925 | Q28: =Q26+Q27 -> -4753.1465 | R28: =R26+R27 -> -5177.5365 | T28: Project recurring cash flows | Y28: =Y26+Y27 -> 27754.639 | Z28: =Z26+Z27 -> 98303.294 | AA28: =AA26+AA27 -> 208323.56 | AB28: =AB26+AB27 -> 360834.47 | AD28: Project recurring cash flows | AI28: =AI26+AI27 -> 1684482.5 | AJ28: =AJ26+AJ27 -> 4419545.2 | AK28: =AK26+AK27 -> 8078745.4 | AL28: =AL26+AL27 -> 9891216.5
D29: Profitability index = | E29: =L40 -> 1.3316509 | F29: =$V$40 -> 14.485668 | G29: =$AF$40 -> 474.47616 | J29: Equipment purchases | N29: =-D6 -> 0 | T29: Equipment purchases | X29: 0 | AD29: Equipment purchases | AH29: 0
D30: Payback = | E30: =L41 -> 1.945236 | F30: =$V$41 -> 1.074516 | G30: =$AF$41 -> 0.02766 | J30: Salvage value | R30: =D7 -> 0 | T30: Salvage value | AB30: =E7 -> 0 | AD30: Salvage value | AL30: =F7 -> 0
D31: Discounted payback = | E31: =L42 -> 1.945236 | F31: =$V$42 -> 1.074516 | G31: =$AF$42 -> 0.02766 | J31: Cash flow due to tax on salvage value (21% rate) | R31: =-(R30-R17)*D21 -> 0 | T31: Cash flow due to tax on salvage value (25% rate) | AB31: =-(AB30-AB17)*E21 -> 0 | AD31: Cash flow due to tax on salvage value (25% rate) | AL31: =-(AL30-AL17)*F21 -> 0
J32: Cash flow due to change in WC | N32: =0-N13 -> -7200 | O32: =N13-O13 -> -17800 | P32: =O13-P13 -> 0 | Q32: =P13-Q13 -> 0 | R32: =Q13-R13 -> 0 | T32: Cash flow due to change in WC | X32: =0-X13 -> -7200 | Y32: =X13-Y13 -> -28400 | Z32: =Y13-Z13 -> -14440 | AA32: =Z13-AA13 -> -19816 | AB32: =AA13-AB13 -> -6985.6 | AD32: Cash flow due to change in WC | AH32: =0-AH13 -> -7200 | AI32: =AH13-AI13 -> -617800 | AJ32: =AI13-AJ13 -> -500000 | AK32: =AJ13-AK13 -> -247600 | AL32: =AK13-AL13 -> -137260
J33: Opportunity cost, after taxes | N33: =E8*(1-E21) -> 21504.743 | O33: =N33 -> 21504.743 | P33: =O33 -> 21504.743 | Q33: =P33 -> 21504.743 | R33: =Q33 -> 21504.743 | T33: Opportunity cost, after taxes | X33: =F8*(1-F21) -> 21417.164 | Y33: =X33 -> 21417.164 | Z33: =Y33 -> 21417.164 | AA33: =Z33 -> 21417.164 | AB33: =AA33 -> 21417.164 | AD33: Opportunity cost, after taxes | AH33: =F8*(1-$G$53) -> 22940 | AI33: =AH33 -> 22940 | AJ33: =AI33 -> 22940 | AK33: =AJ33 -> 22940 | AL33: =AK33 -> 22940
J34: After-tax cannibalization or complementary effect | O34: =-$E$41*(1-$E$53) -> 0 | P34: =O34 -> 0 | Q34: =P34 -> 0 | R34: =Q34 -> 0 | T34: After-tax cannibalization or complementary effect | Y34: =-E9*(1-$F$53) -> 0 | Z34: =Y34 -> 0 | AA34: =Z34 -> 0 | AB34: =AA34 -> 0 | AD34: After-tax cannibalization or complementary effect | AI34: =-$G$41*(1-$G$53) -> 0 | AJ34: =-$G$41*(1-$G$53) -> 0 | AK34: =-$G$41*(1-$G$53) -> 0 | AL34: =-$G$41*(1-$G$53) -> 0
J35: Project cash flows: Time Line | N35: =-N33+(N32) -> -28704.743 | O35: =SUM(O28:O34) -> 11263.718 | P35: =SUM(P28:P34) -> 18451.45 | Q35: =SUM(Q28:Q34) -> 16751.596 | R35: =SUM(R28:R34) -> 16327.206 | T35: Project cash flows: Time Line | X35: =-X33+(X32) -> -28617.164 | Y35: =SUM(Y28:Y34) -> 20771.804 | Z35: =SUM(Z28:Z34) -> 105280.46 | AA35: =SUM(AA28:AA34) -> 209924.73 | AB35: =SUM(AB28:AB34) -> 375266.04 | AD35: Project cash flows: Time Line | AH35: {=-SUM(ABS(AH29:AH34))} -> -30140 | AI35: =SUM(AI28:AI34) -> 1089622.5 | AJ35: =SUM(AJ28:AJ34) -> 3942485.2 | AK35: =SUM(AK28:AK34) -> 7854085.4 | AL35: =SUM(AL28:AL34) -> 9776896.5
J36: Project Evaluation Measures | T36: Project Evaluation Measures | AD36: Project Evaluation Measures
J37: NPV | L37: =NPV($E$22,O35:R35)+N35 -> 9519.9547 | T37: NPV | V37: =NPV(F22,Y35:AB35)+X35 -> 385921.56 | AD37: NPV | AF37: =NPV($G$22,AI35:AL35)+AH35 -> 14270571
J38: IRR | L38: =IRR(N35:R35) -> 0.38047451 | T38: IRR | V38: =IRR(X35:AB35) -> 2.1070146 | AD38: IRR | AF38: =IRR(AH35:AL35) -> 38.624367
J39: MIRR | L39: =MIRR(N35:R35,$E$22,$E$22) -> 0.31056157 | T39: MIRR | V39: =MIRR(X35:AB35,$F$22,$F$22) -> 1.30206 | AD39: MIRR | AF39: =MIRR(AH35:AL35,$G$22,$G$22) -> 4.4139169
J40: Profitability index | L40: =NPV($E$22,O35:R35)/(-N35) -> 1.3316509 | T40: Profitability index | V40: =NPV($F$22,Y35:AB35)/(-X35) -> 14.485668 | AD40: Profitability index | AF40: =NPV($G$22,AI35:AL35)/(-AH35) -> 474.47616
...

Sheet University Success Impact
A1: University Revenue and Gross Profit Assumptions
A3: Scenario | B3: Tech Fee | C3: Platform Cost | D3: Gross Profit Per Student
A4: Low | B4: 48 | C4: 24 | D4: =B4-C4 -> 24
A5: Moderate | B5: 60 | C5: 24 | D5: =B5-C5 -> 36
A6: Ambitious | B6: 96 | C6: 24 | D6: =B6-C6 -> 72
A9: Student Enrollment | B9: Year 1 | C9: Year 2 | D9: Year 3 | E9: Year 4 | F9: Year 5
A10: Baseline | B10: 10000 | C10: 10000 | D10: 10000 | E10: 10000 | F10: 10000
A11: Modest Success | B11: 0.03 | C11: 0.03 | D11: 0.03 | E11: 0.03 | F11: 0.03
A12: Strong Success | B12: 0.07 | C12: 0.07 | D12: 0.07 | E12: 0.07 | F12: 0.07
A13: Flagship Success | B13: 0.12 | C13: 0.12 | D13: 0.12 | E13: 0.12 | F13: 0.12
A16: Gross Profit (Δ in student enrollment) | B16: Year 1 | C16: Year 2 | D16: Year 3 | E16: Year 4 | F16: Year 5
A17: Baseline (No Impact) Low Fee $48 | B17: =B10*$D$4 -> 240000 | C17: =C10*$D$4 -> 240000 | D17: =D10*$D$4 -> 240000 | E17: =E10*$D$4 -> 240000 | F17: =F10*$D$4 -> 240000
A18: 3 % Modest/low Fee $48 | B18: {=$B$10*$D$4*PRODUCT((1+$B$11:B$11))} -> 247200 | C18: {=$B$10*$D$4*PRODUCT((1+$B$11:C$11))} -> 254616 | D18: {=$B$10*$D$4*PRODUCT((1+$B$11:D$11))} -> 262254.48 | E18: {=$B$10*$D$4*PRODUCT((1+$B$11:E$11))} -> 270122.11 | F18: {=$B$10*$D$4*PRODUCT((1+$B$11:F$11))} -> 278225.78
A19: 7% Strong/Low Fee $48 | B19: {=$B$10*$D$4*PRODUCT((1+$B$12:B$12))} -> 256800 | C19: {=$B$10*$D$4*PRODUCT((1+$B$12:C$12))} -> 274776 | D19: {=$B$10*$D$4*PRODUCT((1+$B$12:D$12))} -> 294010.32 | E19: {=$B$10*$D$4*PRODUCT((1+$B$12:E$12))} -> 314591.04 | F19: {=$B$10*$D$4*PRODUCT((1+$B$12:F$12))} -> 336612.42
A20: 12% Flagship/Low Fee $48 | B20: {=$B$10*$D$4*PRODUCT((1+$B$13:B$13))} -> 268800 | C20: {=$B$10*$D$4*PRODUCT((1+$B$13:C$13))} -> 301056 | D20: {=$B$10*$D$4*PRODUCT((1+$B$13:D$13))} -> 337182.72 | E20: {=$B$10*$D$4*PRODUCT((1+$B$13:E$13))} -> 377644.65 | F20: {=$B$10*$D$4*PRODUCT((1+$B$13:F$13))} -> 422962
A23: Gross Profit (Δ in Tech Fee) | B23: Year 1 | C23: Year 2 | D23: Year 3 | E23: Year 4 | F23: Year 5
A24: Baseline Enrollment (low Fee) $48 | B24: =$D$4*B10 -> 240000 | C24: =$D$4*C10 -> 240000 | D24: =$D$4*D10 -> 240000 | E24: =$D$4*E10 -> 240000 | F24: =$D$4*F10 -> 240000
A25: Baseline Enrollment (moderate Fee) $60 | B25: =$D$5*B10 -> 360000 | C25: =$D$5*C10 -> 360000 | D25: =$D$5*D10 -> 360000 | E25: =$D$5*E10 -> 360000 | F25: =$D$5*F10 -> 360000
A26: Baseline Enrollment (Ambitious Fee) $96 | B26: =$D$6*B10 -> 720000 | C26: =$D$6*C10 -> 720000 | D26: =$D$6*D10 -> 720000 | E26: =$D$6*E10 -> 720000 | F26: =$D$6*F10 -> 720000
